Traceback (most recent call last):
  File "/home/runner/work/omniverse/omniverse/.venv/lib/python3.12/site-packages/jupyter_core/utils/__init__.py", line 154, in wrapped
    asyncio.get_running_loop()
RuntimeError: no running event loop

During handling of the above exception, another exception occurred:

Traceback (most recent call last):
  File "/home/runner/work/omniverse/omniverse/.venv/lib/python3.12/site-packages/jupyter_cache/executors/utils.py", line 58, in single_nb_execution
    executenb(
  File "/home/runner/work/omniverse/omniverse/.venv/lib/python3.12/site-packages/nbclient/client.py", line 1319, in execute
    return NotebookClient(nb=nb, resources=resources, km=km, **kwargs).execute()
           ^^^^^^^^^^^^^^^^^^^^^^^^^^^^^^^^^^^^^^^^^^^^^^^^^^^^^^^^^^^^^^^^^^^^^
  File "/home/runner/work/omniverse/omniverse/.venv/lib/python3.12/site-packages/jupyter_core/utils/__init__.py", line 158, in wrapped
    return loop.run_until_complete(inner)
           ^^^^^^^^^^^^^^^^^^^^^^^^^^^^^^
  File "/usr/lib/python3.12/asyncio/base_events.py", line 687, in run_until_complete
    return future.result()
           ^^^^^^^^^^^^^^^
  File "/home/runner/work/omniverse/omniverse/.venv/lib/python3.12/site-packages/nbclient/client.py", line 709, in async_execute
    await self.async_execute_cell(
  File "/home/runner/work/omniverse/omniverse/.venv/lib/python3.12/site-packages/nbclient/client.py", line 1062, in async_execute_cell
    await self._check_raise_for_error(cell, cell_index, exec_reply)
  File "/home/runner/work/omniverse/omniverse/.venv/lib/python3.12/site-packages/nbclient/client.py", line 918, in _check_raise_for_error
    raise CellExecutionError.from_cell_and_msg(cell, exec_reply_content)
nbclient.exceptions.CellExecutionError: An error occurred while executing the following cell:
------------------
from collections import OrderedDict
from dataclasses import dataclass
from enum import Enum, IntEnum
from typing import Dict, Literal, Optional

import pandas as pd
from pydantic import BaseModel
from rich.pretty import pprint
from tabulate import tabulate
from torch import nn
from transformers import GPT2LMHeadModel
------------------


[31m---------------------------------------------------------------------------[39m
[31mModuleNotFoundError[39m                       Traceback (most recent call last)
[36mCell[39m[36m [39m[32mIn[1][39m[32m, line 11[39m
[32m      9[39m [38;5;28;01mfrom[39;00m[38;5;250m [39m[34;01mtabulate[39;00m[38;5;250m [39m[38;5;28;01mimport[39;00m tabulate
[32m     10[39m [38;5;28;01mfrom[39;00m[38;5;250m [39m[34;01mtorch[39;00m[38;5;250m [39m[38;5;28;01mimport[39;00m nn
[32m---> [39m[32m11[39m [38;5;28;01mfrom[39;00m[38;5;250m [39m[34;01mtransformers[39;00m[38;5;250m [39m[38;5;28;01mimport[39;00m GPT2LMHeadModel

[31mModuleNotFoundError[39m: No module named 'transformers'

